#VRML_SIM R2023b utf8

EXTERNPROTO "https://raw.githubusercontent.com/cyberbotics/webots/R2023a/projects/objects/backgrounds/protos/TexturedBackground.proto"
EXTERNPROTO "https://raw.githubusercontent.com/cyberbotics/webots/R2023a/projects/objects/backgrounds/protos/TexturedBackgroundLight.proto"
EXTERNPROTO "https://raw.githubusercontent.com/cyberbotics/webots/R2023a/projects/objects/floors/protos/Floor.proto"
EXTERNPROTO "https://raw.githubusercontent.com/cyberbotics/webots/R2023b/projects/appearances/protos/Rubber.proto"
EXTERNPROTO "https://raw.githubusercontent.com/cyberbotics/webots/R2023b/projects/objects/tables/protos/Table.proto"
EXTERNPROTO "https://raw.githubusercontent.com/cyberbotics/webots/R2023b/projects/objects/kitchen/utensils/protos/Plate.proto"
EXTERNPROTO "https://raw.githubusercontent.com/cyberbotics/webots/R2023b/projects/objects/kitchen/breakfast/protos/BiscuitBox.proto"
EXTERNPROTO "https://raw.githubusercontent.com/cyberbotics/webots/R2023b/projects/objects/kitchen/breakfast/protos/JamJar.proto"
EXTERNPROTO "https://raw.githubusercontent.com/cyberbotics/webots/R2023b/projects/objects/kitchen/utensils/protos/Glass.proto"
EXTERNPROTO "https://raw.githubusercontent.com/cyberbotics/webots/R2023b/projects/appearances/protos/RoughPine.proto"

WorldInfo {
  basicTimeStep 16
}
Viewpoint {
  orientation -0.19444017749540524 -0.058347873484007544 0.9791774829087163 3.713185912090328
  position 1.9184304621757196 1.3597037395221327 1.2834070497194128
}
TexturedBackground {
}
TexturedBackgroundLight {
}
Floor {
  size 5 5
}
Robot {
  translation 0 0 0.1
  children [
    HingeJoint {
      jointParameters HingeJointParameters {
        axis 0 1 0
        anchor 0 0.125 0
      }
      device [
        PositionSensor {
          name "right wheel sensor"
        }
        RotationalMotor {
          name "right wheel motor"
        }
      ]
      endPoint Solid {
        translation 0 0.124999 0
        rotation 1 0 0 1.5707996938995747
        children [
          DEF WHEEL_SHAPE Shape {
            appearance Rubber {
            }
            geometry Cylinder {
              height 0.05
              radius 0.1
            }
          }
        ]
        name "Right Wheel"
        boundingObject USE WHEEL_SHAPE
        physics Physics {
        }
      }
    }
    HingeJoint {
      jointParameters HingeJointParameters {
        axis 0 1 0
        anchor 0 -0.125 0
      }
      device [
        PositionSensor {
          name "left wheel sensor"
        }
        RotationalMotor {
          name "left wheel motor"
        }
      ]
      endPoint Solid {
        translation 0 -0.125 0
        rotation 1 0 0 1.570790895516373
        children [
          DEF WHEEL_SHAPE Shape {
            appearance Rubber {
            }
            geometry Cylinder {
              height 0.05
              radius 0.1
            }
          }
        ]
        name "Left Wheel"
        boundingObject USE WHEEL_SHAPE
        physics Physics {
        }
      }
    }
    Solid {
      children [
        DEF BODY_SHAPE Shape {
          appearance Appearance {
            material Material {
              diffuseColor 0 0.333333 1
            }
          }
          geometry Box {
            size 0.1 0.25 0.1
          }
        }
      ]
      name "Body"
      boundingObject USE BODY_SHAPE
      physics Physics {
      }
    }
    Accelerometer {
    }
    InertialUnit {
    }
    GPS {
    }
    Gyro {
    }
    Group {
      children [
        SliderJoint {
          jointParameters JointParameters {
            position 0.15
            maxStop 0.3
            springConstant 10
            dampingConstant 5
            staticFriction 15
          }
          device [
            LinearMotor {
              maxPosition 0.3
            }
          ]
          endPoint Solid {
            translation 0 0 0.35
            children [
              DEF UPPER_STICK_SHAPE Group {
                children [
                  Shape {
                    geometry Cylinder {
                      height 0.3
                      radius 0.01
                    }
                  }
                  Pose {
                    translation 0 0 0.155
                    children [
                      Shape {
                        geometry Cylinder {
                          height 0.01
                          radius 0.15
                        }
                      }
                    ]
                  }
                ]
              }
            ]
            boundingObject USE UPPER_STICK_SHAPE
            physics Physics {
            }
          }
        }
        Solid {
          translation 0 0 0.2
          rotation 1 0 0 0
          children [
            DEF STICK_SHAPE Shape {
              geometry Cylinder {
                height 0.3
                radius 0.01
              }
            }
          ]
          name "stick"
          boundingObject USE STICK_SHAPE
          physics Physics {
          }
        }
      ]
    }
    DistanceSensor {
      translation 0.055 0.041 0
      children [
        DEF DIS_SENSOR_SHAPE Shape {
          appearance PBRAppearance {
            metalness 0
          }
          geometry Box {
            size 0.01 0.01 0.01
          }
        }
      ]
      name "FL distance sensor"
    }
    DistanceSensor {
      translation 0.055 -0.041 0
      children [
        DEF DIS_SENSOR_SHAPE Shape {
          appearance PBRAppearance {
            metalness 0
          }
          geometry Box {
            size 0.01 0.01 0.01
          }
        }
      ]
      name "FR distance sensor"
    }
    DistanceSensor {
      translation -0.055 0.041 0
      rotation 0 0 1 3.141592653589793
      children [
        DEF DIS_SENSOR_SHAPE Shape {
          appearance PBRAppearance {
            metalness 0
          }
          geometry Box {
            size 0.01 0.01 0.01
          }
        }
      ]
      name "RL distance sensor"
    }
    DistanceSensor {
      translation -0.055 -0.041 0
      rotation 0 0 1 3.141592653589793
      children [
        DEF DIS_SENSOR_SHAPE Shape {
          appearance PBRAppearance {
            metalness 0
          }
          geometry Box {
            size 0.01 0.01 0.01
          }
        }
      ]
      name "RR distance sensor"
    }
  ]
  boundingObject USE BODY_SHAPE
  physics Physics {
  }
  controller "inverted_pendulum"
}
Table {
  translation -2.03446 -1.54056 1.08358e-13
  rotation 0 0 1 1.5707996938995747
  size 1.5 0.9 0.61
  feetSize 0.05 0.05
}
Plate {
  translation -2.02719 -1.85997 0.62
}
JamJar {
  translation -2.30975 -0.8871 0.62
}
Glass {
  translation -2.06508 -1.69057 0.62
}
BiscuitBox {
  translation -2.23313 -1.75006 0.632
}
Solid {
  translation -2.01496 -1.36277 0.7
  children [
    Group {
      children [
        Pose {
          translation 0 -0.15 -0.025
          children [
            DEF TRAY_BASE_SHAPE Shape {
              appearance RoughPine {
              }
              geometry Box {
                size 0.4 0.05 0.025
              }
            }
          ]
        }
        Pose {
          translation 0 0.15 -0.025
          children [
            USE TRAY_BASE_SHAPE
          ]
        }
        Pose {
          children [
            Shape {
              appearance RoughPine {
              }
              geometry Box {
                size 0.4 0.35 0.025
              }
            }
          ]
        }
      ]
    }
  ]
}
